{
 "cells": [
  {
   "cell_type": "code",
   "execution_count": null,
   "metadata": {},
   "outputs": [],
   "source": [
    "import tensorflow as tf\n",
    "from tensorflow.keras.preprocessing.image import ImageDataGenerator\n",
    "import matplotlib.pyplot as plt\n",
    "import pandas as pd\n",
    "import numpy as np\n",
    "\n",
    "import PIL.Image as Image"
   ]
  },
  {
   "cell_type": "code",
   "execution_count": 7,
   "metadata": {},
   "outputs": [],
   "source": [
    "def load_dataframe(path):\n",
    "    df = pd.read_csv(path)\n",
    "    df = df.dropna()\n",
    "    df = df.reset_index(drop=True)\n",
    "    return df\n",
    "\n",
    "train_path = '/home/jon/development/university/sis/cv_api/data/sign_mnist/sign_mnist_train.csv'\n",
    "test_path = '/home/jon/development/university/sis/cv_api/data/sign_mnist/sign_mnist_test.csv'\n",
    "\n",
    "train_dataframe = load_dataframe(train_path)\n",
    "test_dataframe = load_dataframe(test_path)\n"
   ]
  },
  {
   "cell_type": "code",
   "execution_count": 8,
   "metadata": {},
   "outputs": [],
   "source": [
    "def form_datasets(labels, images):\n",
    "    if len(labels) != len(images):\n",
    "        raise Exception('The number of labels and images are not the same.')\n",
    "\n",
    "    output_labels = []\n",
    "    output_images = []\n",
    "\n",
    "    for x in range(len(labels)):\n",
    "        label = labels[x]\n",
    "        image = images[x]\n",
    "        image = image.reshape((28, 28))\n",
    "\n",
    "        output_labels.append(label)\n",
    "        output_images.append(image)\n",
    "\n",
    "    return np.array(output_labels).astype(float), np.array(output_images).astype(float)\n",
    "\n",
    "\n",
    "train_labels, train_images = form_datasets(train_dataframe['label'].to_numpy(), train_dataframe.drop('label', axis=1).to_numpy())\n",
    "test_labels, test_images = form_datasets(test_dataframe['label'].to_numpy(), test_dataframe.drop('label', axis=1).to_numpy())\n",
    "\n",
    "train_images = np.expand_dims(train_images, axis=3) # Expanding Dimension for Convolutional Layer\n",
    "test_images = np.expand_dims(test_images, axis=3) # Expanding Dimension for Convolutional Layer"
   ]
  },
  {
   "cell_type": "code",
   "execution_count": 9,
   "metadata": {},
   "outputs": [],
   "source": [
    "def getImageGenerators(training_labels, training_images, test_labels, test_images):\n",
    "    datagen = ImageDataGenerator(\n",
    "        rescale=1./255,\n",
    "        rotation_range=40,\n",
    "        width_shift_range=0.2,\n",
    "        height_shift_range=0.2,\n",
    "        shear_range=0.2,\n",
    "        horizontal_flip=True,\n",
    "        zoom_range=0.2,\n",
    "        fill_mode='nearest'\n",
    "    )\n",
    "\n",
    "    test_datagen = ImageDataGenerator(\n",
    "        rescale=1./255\n",
    "    )\n",
    "\n",
    "    train_generator = datagen.flow(x=training_images, y=training_labels, batch_size=32)\n",
    "    test_generator = test_datagen.flow(x=test_images, y=test_labels, batch_size=32)\n",
    "\n",
    "    return train_generator, test_generator\n",
    "\n",
    "train_generator, test_generator = getImageGenerators(train_labels, train_images, test_labels, test_images)"
   ]
  },
  {
   "cell_type": "code",
   "execution_count": 10,
   "metadata": {},
   "outputs": [
    {
     "name": "stdout",
     "output_type": "stream",
     "text": [
      "Epoch 1/20\n"
     ]
    },
    {
     "name": "stderr",
     "output_type": "stream",
     "text": [
      "2023-08-29 21:47:43.821891: I tensorflow/core/common_runtime/executor.cc:1197] [/device:CPU:0] (DEBUG INFO) Executor start aborting (this does not indicate an error and you can ignore this message): INVALID_ARGUMENT: You must feed a value for placeholder tensor 'Placeholder/_0' with dtype int32\n",
      "\t [[{{node Placeholder/_0}}]]\n",
      "2023-08-29 21:47:44.337233: W tensorflow/compiler/xla/service/gpu/llvm_gpu_backend/gpu_backend_lib.cc:274] libdevice is required by this HLO module but was not found at ./libdevice.10.bc\n",
      "2023-08-29 21:47:44.337810: W tensorflow/core/framework/op_kernel.cc:1830] OP_REQUIRES failed at xla_ops.cc:362 : INTERNAL: libdevice not found at ./libdevice.10.bc\n",
      "2023-08-29 21:47:44.337832: I tensorflow/core/common_runtime/executor.cc:1197] [/job:localhost/replica:0/task:0/device:GPU:0] (DEBUG INFO) Executor start aborting (this does not indicate an error and you can ignore this message): INTERNAL: libdevice not found at ./libdevice.10.bc\n",
      "\t [[{{node StatefulPartitionedCall_6}}]]\n",
      "2023-08-29 21:47:44.351696: W tensorflow/compiler/xla/service/gpu/llvm_gpu_backend/gpu_backend_lib.cc:274] libdevice is required by this HLO module but was not found at ./libdevice.10.bc\n",
      "2023-08-29 21:47:44.351876: W tensorflow/core/framework/op_kernel.cc:1830] OP_REQUIRES failed at xla_ops.cc:362 : INTERNAL: libdevice not found at ./libdevice.10.bc\n",
      "2023-08-29 21:47:44.364710: W tensorflow/compiler/xla/service/gpu/llvm_gpu_backend/gpu_backend_lib.cc:274] libdevice is required by this HLO module but was not found at ./libdevice.10.bc\n",
      "2023-08-29 21:47:44.364912: W tensorflow/core/framework/op_kernel.cc:1830] OP_REQUIRES failed at xla_ops.cc:362 : INTERNAL: libdevice not found at ./libdevice.10.bc\n",
      "2023-08-29 21:47:44.377921: W tensorflow/compiler/xla/service/gpu/llvm_gpu_backend/gpu_backend_lib.cc:274] libdevice is required by this HLO module but was not found at ./libdevice.10.bc\n",
      "2023-08-29 21:47:44.378143: W tensorflow/core/framework/op_kernel.cc:1830] OP_REQUIRES failed at xla_ops.cc:362 : INTERNAL: libdevice not found at ./libdevice.10.bc\n",
      "2023-08-29 21:47:44.391526: W tensorflow/compiler/xla/service/gpu/llvm_gpu_backend/gpu_backend_lib.cc:274] libdevice is required by this HLO module but was not found at ./libdevice.10.bc\n",
      "2023-08-29 21:47:44.391685: W tensorflow/core/framework/op_kernel.cc:1830] OP_REQUIRES failed at xla_ops.cc:362 : INTERNAL: libdevice not found at ./libdevice.10.bc\n",
      "2023-08-29 21:47:44.403048: W tensorflow/compiler/xla/service/gpu/llvm_gpu_backend/gpu_backend_lib.cc:274] libdevice is required by this HLO module but was not found at ./libdevice.10.bc\n",
      "2023-08-29 21:47:44.403176: W tensorflow/core/framework/op_kernel.cc:1830] OP_REQUIRES failed at xla_ops.cc:362 : INTERNAL: libdevice not found at ./libdevice.10.bc\n",
      "2023-08-29 21:47:44.415671: W tensorflow/compiler/xla/service/gpu/llvm_gpu_backend/gpu_backend_lib.cc:274] libdevice is required by this HLO module but was not found at ./libdevice.10.bc\n",
      "2023-08-29 21:47:44.415820: W tensorflow/core/framework/op_kernel.cc:1830] OP_REQUIRES failed at xla_ops.cc:362 : INTERNAL: libdevice not found at ./libdevice.10.bc\n",
      "2023-08-29 21:47:44.427263: W tensorflow/compiler/xla/service/gpu/llvm_gpu_backend/gpu_backend_lib.cc:274] libdevice is required by this HLO module but was not found at ./libdevice.10.bc\n",
      "2023-08-29 21:47:44.427402: W tensorflow/core/framework/op_kernel.cc:1830] OP_REQUIRES failed at xla_ops.cc:362 : INTERNAL: libdevice not found at ./libdevice.10.bc\n"
     ]
    },
    {
     "ename": "InternalError",
     "evalue": "Graph execution error:\n\nDetected at node 'StatefulPartitionedCall_6' defined at (most recent call last):\n    File \"<frozen runpy>\", line 198, in _run_module_as_main\n    File \"<frozen runpy>\", line 88, in _run_code\n    File \"/home/jon/miniconda3/envs/sis_cv_api/lib/python3.11/site-packages/ipykernel_launcher.py\", line 17, in <module>\n      app.launch_new_instance()\n    File \"/home/jon/miniconda3/envs/sis_cv_api/lib/python3.11/site-packages/traitlets/config/application.py\", line 1043, in launch_instance\n      app.start()\n    File \"/home/jon/miniconda3/envs/sis_cv_api/lib/python3.11/site-packages/ipykernel/kernelapp.py\", line 736, in start\n      self.io_loop.start()\n    File \"/home/jon/miniconda3/envs/sis_cv_api/lib/python3.11/site-packages/tornado/platform/asyncio.py\", line 195, in start\n      self.asyncio_loop.run_forever()\n    File \"/home/jon/miniconda3/envs/sis_cv_api/lib/python3.11/asyncio/base_events.py\", line 607, in run_forever\n      self._run_once()\n    File \"/home/jon/miniconda3/envs/sis_cv_api/lib/python3.11/asyncio/base_events.py\", line 1922, in _run_once\n      handle._run()\n    File \"/home/jon/miniconda3/envs/sis_cv_api/lib/python3.11/asyncio/events.py\", line 80, in _run\n      self._context.run(self._callback, *self._args)\n    File \"/home/jon/miniconda3/envs/sis_cv_api/lib/python3.11/site-packages/ipykernel/kernelbase.py\", line 516, in dispatch_queue\n      await self.process_one()\n    File \"/home/jon/miniconda3/envs/sis_cv_api/lib/python3.11/site-packages/ipykernel/kernelbase.py\", line 505, in process_one\n      await dispatch(*args)\n    File \"/home/jon/miniconda3/envs/sis_cv_api/lib/python3.11/site-packages/ipykernel/kernelbase.py\", line 412, in dispatch_shell\n      await result\n    File \"/home/jon/miniconda3/envs/sis_cv_api/lib/python3.11/site-packages/ipykernel/kernelbase.py\", line 740, in execute_request\n      reply_content = await reply_content\n    File \"/home/jon/miniconda3/envs/sis_cv_api/lib/python3.11/site-packages/ipykernel/ipkernel.py\", line 422, in do_execute\n      res = shell.run_cell(\n    File \"/home/jon/miniconda3/envs/sis_cv_api/lib/python3.11/site-packages/ipykernel/zmqshell.py\", line 546, in run_cell\n      return super().run_cell(*args, **kwargs)\n    File \"/home/jon/miniconda3/envs/sis_cv_api/lib/python3.11/site-packages/IPython/core/interactiveshell.py\", line 3009, in run_cell\n      result = self._run_cell(\n    File \"/home/jon/miniconda3/envs/sis_cv_api/lib/python3.11/site-packages/IPython/core/interactiveshell.py\", line 3064, in _run_cell\n      result = runner(coro)\n    File \"/home/jon/miniconda3/envs/sis_cv_api/lib/python3.11/site-packages/IPython/core/async_helpers.py\", line 129, in _pseudo_sync_runner\n      coro.send(None)\n    File \"/home/jon/miniconda3/envs/sis_cv_api/lib/python3.11/site-packages/IPython/core/interactiveshell.py\", line 3269, in run_cell_async\n      has_raised = await self.run_ast_nodes(code_ast.body, cell_name,\n    File \"/home/jon/miniconda3/envs/sis_cv_api/lib/python3.11/site-packages/IPython/core/interactiveshell.py\", line 3448, in run_ast_nodes\n      if await self.run_code(code, result, async_=asy):\n    File \"/home/jon/miniconda3/envs/sis_cv_api/lib/python3.11/site-packages/IPython/core/interactiveshell.py\", line 3508, in run_code\n      exec(code_obj, self.user_global_ns, self.user_ns)\n    File \"/tmp/ipykernel_40843/2658873072.py\", line 19, in <module>\n      history = model.fit(train_generator, epochs=epochs, validation_data=test_generator)\n    File \"/home/jon/miniconda3/envs/sis_cv_api/lib/python3.11/site-packages/keras/utils/traceback_utils.py\", line 65, in error_handler\n      return fn(*args, **kwargs)\n    File \"/home/jon/miniconda3/envs/sis_cv_api/lib/python3.11/site-packages/keras/engine/training.py\", line 1685, in fit\n      tmp_logs = self.train_function(iterator)\n    File \"/home/jon/miniconda3/envs/sis_cv_api/lib/python3.11/site-packages/keras/engine/training.py\", line 1284, in train_function\n      return step_function(self, iterator)\n    File \"/home/jon/miniconda3/envs/sis_cv_api/lib/python3.11/site-packages/keras/engine/training.py\", line 1268, in step_function\n      outputs = model.distribute_strategy.run(run_step, args=(data,))\n    File \"/home/jon/miniconda3/envs/sis_cv_api/lib/python3.11/site-packages/keras/engine/training.py\", line 1249, in run_step\n      outputs = model.train_step(data)\n    File \"/home/jon/miniconda3/envs/sis_cv_api/lib/python3.11/site-packages/keras/engine/training.py\", line 1054, in train_step\n      self.optimizer.minimize(loss, self.trainable_variables, tape=tape)\n    File \"/home/jon/miniconda3/envs/sis_cv_api/lib/python3.11/site-packages/keras/optimizers/optimizer.py\", line 543, in minimize\n      self.apply_gradients(grads_and_vars)\n    File \"/home/jon/miniconda3/envs/sis_cv_api/lib/python3.11/site-packages/keras/optimizers/optimizer.py\", line 1174, in apply_gradients\n      return super().apply_gradients(grads_and_vars, name=name)\n    File \"/home/jon/miniconda3/envs/sis_cv_api/lib/python3.11/site-packages/keras/optimizers/optimizer.py\", line 650, in apply_gradients\n      iteration = self._internal_apply_gradients(grads_and_vars)\n    File \"/home/jon/miniconda3/envs/sis_cv_api/lib/python3.11/site-packages/keras/optimizers/optimizer.py\", line 1200, in _internal_apply_gradients\n      return tf.__internal__.distribute.interim.maybe_merge_call(\n    File \"/home/jon/miniconda3/envs/sis_cv_api/lib/python3.11/site-packages/keras/optimizers/optimizer.py\", line 1250, in _distributed_apply_gradients_fn\n      distribution.extended.update(\n    File \"/home/jon/miniconda3/envs/sis_cv_api/lib/python3.11/site-packages/keras/optimizers/optimizer.py\", line 1245, in apply_grad_to_update_var\n      return self._update_step_xla(grad, var, id(self._var_key(var)))\nNode: 'StatefulPartitionedCall_6'\nlibdevice not found at ./libdevice.10.bc\n\t [[{{node StatefulPartitionedCall_6}}]] [Op:__inference_train_function_2225]",
     "output_type": "error",
     "traceback": [
      "\u001b[0;31m---------------------------------------------------------------------------\u001b[0m",
      "\u001b[0;31mInternalError\u001b[0m                             Traceback (most recent call last)",
      "Cell \u001b[0;32mIn[10], line 19\u001b[0m\n\u001b[1;32m     16\u001b[0m model \u001b[39m=\u001b[39m build_model()\n\u001b[1;32m     18\u001b[0m epochs \u001b[39m=\u001b[39m \u001b[39m20\u001b[39m\n\u001b[0;32m---> 19\u001b[0m history \u001b[39m=\u001b[39m model\u001b[39m.\u001b[39;49mfit(train_generator, epochs\u001b[39m=\u001b[39;49mepochs, validation_data\u001b[39m=\u001b[39;49mtest_generator)\n\u001b[1;32m     21\u001b[0m model\u001b[39m.\u001b[39msummary()\n",
      "File \u001b[0;32m~/miniconda3/envs/sis_cv_api/lib/python3.11/site-packages/keras/utils/traceback_utils.py:70\u001b[0m, in \u001b[0;36mfilter_traceback.<locals>.error_handler\u001b[0;34m(*args, **kwargs)\u001b[0m\n\u001b[1;32m     67\u001b[0m     filtered_tb \u001b[39m=\u001b[39m _process_traceback_frames(e\u001b[39m.\u001b[39m__traceback__)\n\u001b[1;32m     68\u001b[0m     \u001b[39m# To get the full stack trace, call:\u001b[39;00m\n\u001b[1;32m     69\u001b[0m     \u001b[39m# `tf.debugging.disable_traceback_filtering()`\u001b[39;00m\n\u001b[0;32m---> 70\u001b[0m     \u001b[39mraise\u001b[39;00m e\u001b[39m.\u001b[39mwith_traceback(filtered_tb) \u001b[39mfrom\u001b[39;00m \u001b[39mNone\u001b[39;00m\n\u001b[1;32m     71\u001b[0m \u001b[39mfinally\u001b[39;00m:\n\u001b[1;32m     72\u001b[0m     \u001b[39mdel\u001b[39;00m filtered_tb\n",
      "File \u001b[0;32m~/miniconda3/envs/sis_cv_api/lib/python3.11/site-packages/tensorflow/python/eager/execute.py:52\u001b[0m, in \u001b[0;36mquick_execute\u001b[0;34m(op_name, num_outputs, inputs, attrs, ctx, name)\u001b[0m\n\u001b[1;32m     50\u001b[0m \u001b[39mtry\u001b[39;00m:\n\u001b[1;32m     51\u001b[0m   ctx\u001b[39m.\u001b[39mensure_initialized()\n\u001b[0;32m---> 52\u001b[0m   tensors \u001b[39m=\u001b[39m pywrap_tfe\u001b[39m.\u001b[39mTFE_Py_Execute(ctx\u001b[39m.\u001b[39m_handle, device_name, op_name,\n\u001b[1;32m     53\u001b[0m                                       inputs, attrs, num_outputs)\n\u001b[1;32m     54\u001b[0m \u001b[39mexcept\u001b[39;00m core\u001b[39m.\u001b[39m_NotOkStatusException \u001b[39mas\u001b[39;00m e:\n\u001b[1;32m     55\u001b[0m   \u001b[39mif\u001b[39;00m name \u001b[39mis\u001b[39;00m \u001b[39mnot\u001b[39;00m \u001b[39mNone\u001b[39;00m:\n",
      "\u001b[0;31mInternalError\u001b[0m: Graph execution error:\n\nDetected at node 'StatefulPartitionedCall_6' defined at (most recent call last):\n    File \"<frozen runpy>\", line 198, in _run_module_as_main\n    File \"<frozen runpy>\", line 88, in _run_code\n    File \"/home/jon/miniconda3/envs/sis_cv_api/lib/python3.11/site-packages/ipykernel_launcher.py\", line 17, in <module>\n      app.launch_new_instance()\n    File \"/home/jon/miniconda3/envs/sis_cv_api/lib/python3.11/site-packages/traitlets/config/application.py\", line 1043, in launch_instance\n      app.start()\n    File \"/home/jon/miniconda3/envs/sis_cv_api/lib/python3.11/site-packages/ipykernel/kernelapp.py\", line 736, in start\n      self.io_loop.start()\n    File \"/home/jon/miniconda3/envs/sis_cv_api/lib/python3.11/site-packages/tornado/platform/asyncio.py\", line 195, in start\n      self.asyncio_loop.run_forever()\n    File \"/home/jon/miniconda3/envs/sis_cv_api/lib/python3.11/asyncio/base_events.py\", line 607, in run_forever\n      self._run_once()\n    File \"/home/jon/miniconda3/envs/sis_cv_api/lib/python3.11/asyncio/base_events.py\", line 1922, in _run_once\n      handle._run()\n    File \"/home/jon/miniconda3/envs/sis_cv_api/lib/python3.11/asyncio/events.py\", line 80, in _run\n      self._context.run(self._callback, *self._args)\n    File \"/home/jon/miniconda3/envs/sis_cv_api/lib/python3.11/site-packages/ipykernel/kernelbase.py\", line 516, in dispatch_queue\n      await self.process_one()\n    File \"/home/jon/miniconda3/envs/sis_cv_api/lib/python3.11/site-packages/ipykernel/kernelbase.py\", line 505, in process_one\n      await dispatch(*args)\n    File \"/home/jon/miniconda3/envs/sis_cv_api/lib/python3.11/site-packages/ipykernel/kernelbase.py\", line 412, in dispatch_shell\n      await result\n    File \"/home/jon/miniconda3/envs/sis_cv_api/lib/python3.11/site-packages/ipykernel/kernelbase.py\", line 740, in execute_request\n      reply_content = await reply_content\n    File \"/home/jon/miniconda3/envs/sis_cv_api/lib/python3.11/site-packages/ipykernel/ipkernel.py\", line 422, in do_execute\n      res = shell.run_cell(\n    File \"/home/jon/miniconda3/envs/sis_cv_api/lib/python3.11/site-packages/ipykernel/zmqshell.py\", line 546, in run_cell\n      return super().run_cell(*args, **kwargs)\n    File \"/home/jon/miniconda3/envs/sis_cv_api/lib/python3.11/site-packages/IPython/core/interactiveshell.py\", line 3009, in run_cell\n      result = self._run_cell(\n    File \"/home/jon/miniconda3/envs/sis_cv_api/lib/python3.11/site-packages/IPython/core/interactiveshell.py\", line 3064, in _run_cell\n      result = runner(coro)\n    File \"/home/jon/miniconda3/envs/sis_cv_api/lib/python3.11/site-packages/IPython/core/async_helpers.py\", line 129, in _pseudo_sync_runner\n      coro.send(None)\n    File \"/home/jon/miniconda3/envs/sis_cv_api/lib/python3.11/site-packages/IPython/core/interactiveshell.py\", line 3269, in run_cell_async\n      has_raised = await self.run_ast_nodes(code_ast.body, cell_name,\n    File \"/home/jon/miniconda3/envs/sis_cv_api/lib/python3.11/site-packages/IPython/core/interactiveshell.py\", line 3448, in run_ast_nodes\n      if await self.run_code(code, result, async_=asy):\n    File \"/home/jon/miniconda3/envs/sis_cv_api/lib/python3.11/site-packages/IPython/core/interactiveshell.py\", line 3508, in run_code\n      exec(code_obj, self.user_global_ns, self.user_ns)\n    File \"/tmp/ipykernel_40843/2658873072.py\", line 19, in <module>\n      history = model.fit(train_generator, epochs=epochs, validation_data=test_generator)\n    File \"/home/jon/miniconda3/envs/sis_cv_api/lib/python3.11/site-packages/keras/utils/traceback_utils.py\", line 65, in error_handler\n      return fn(*args, **kwargs)\n    File \"/home/jon/miniconda3/envs/sis_cv_api/lib/python3.11/site-packages/keras/engine/training.py\", line 1685, in fit\n      tmp_logs = self.train_function(iterator)\n    File \"/home/jon/miniconda3/envs/sis_cv_api/lib/python3.11/site-packages/keras/engine/training.py\", line 1284, in train_function\n      return step_function(self, iterator)\n    File \"/home/jon/miniconda3/envs/sis_cv_api/lib/python3.11/site-packages/keras/engine/training.py\", line 1268, in step_function\n      outputs = model.distribute_strategy.run(run_step, args=(data,))\n    File \"/home/jon/miniconda3/envs/sis_cv_api/lib/python3.11/site-packages/keras/engine/training.py\", line 1249, in run_step\n      outputs = model.train_step(data)\n    File \"/home/jon/miniconda3/envs/sis_cv_api/lib/python3.11/site-packages/keras/engine/training.py\", line 1054, in train_step\n      self.optimizer.minimize(loss, self.trainable_variables, tape=tape)\n    File \"/home/jon/miniconda3/envs/sis_cv_api/lib/python3.11/site-packages/keras/optimizers/optimizer.py\", line 543, in minimize\n      self.apply_gradients(grads_and_vars)\n    File \"/home/jon/miniconda3/envs/sis_cv_api/lib/python3.11/site-packages/keras/optimizers/optimizer.py\", line 1174, in apply_gradients\n      return super().apply_gradients(grads_and_vars, name=name)\n    File \"/home/jon/miniconda3/envs/sis_cv_api/lib/python3.11/site-packages/keras/optimizers/optimizer.py\", line 650, in apply_gradients\n      iteration = self._internal_apply_gradients(grads_and_vars)\n    File \"/home/jon/miniconda3/envs/sis_cv_api/lib/python3.11/site-packages/keras/optimizers/optimizer.py\", line 1200, in _internal_apply_gradients\n      return tf.__internal__.distribute.interim.maybe_merge_call(\n    File \"/home/jon/miniconda3/envs/sis_cv_api/lib/python3.11/site-packages/keras/optimizers/optimizer.py\", line 1250, in _distributed_apply_gradients_fn\n      distribution.extended.update(\n    File \"/home/jon/miniconda3/envs/sis_cv_api/lib/python3.11/site-packages/keras/optimizers/optimizer.py\", line 1245, in apply_grad_to_update_var\n      return self._update_step_xla(grad, var, id(self._var_key(var)))\nNode: 'StatefulPartitionedCall_6'\nlibdevice not found at ./libdevice.10.bc\n\t [[{{node StatefulPartitionedCall_6}}]] [Op:__inference_train_function_2225]"
     ]
    }
   ],
   "source": [
    "def build_model():\n",
    "    model = tf.keras.Sequential([\n",
    "        tf.keras.layers.Conv2D(32, (3, 3), activation='relu', input_shape=(28, 28, 1)),\n",
    "        tf.keras.layers.MaxPool2D((2, 2)),\n",
    "        tf.keras.layers.Conv2D(32, (3, 3), activation='relu'),\n",
    "        tf.keras.layers.MaxPool2D((2, 2)),\n",
    "        tf.keras.layers.Flatten(),\n",
    "        tf.keras.layers.Dense(512, activation='relu'),\n",
    "        tf.keras.layers.Dense(26, activation='softmax')\n",
    "    ])\n",
    "\n",
    "    model.compile(optimizer='adam', loss='sparse_categorical_crossentropy', metrics=['accuracy'])\n",
    "\n",
    "    return model\n",
    "\n",
    "model = build_model()\n",
    "\n",
    "epochs = 20\n",
    "history = model.fit(train_generator, epochs=epochs, validation_data=test_generator)\n",
    "\n",
    "model.summary()"
   ]
  },
  {
   "cell_type": "code",
   "execution_count": null,
   "metadata": {},
   "outputs": [
    {
     "ename": "",
     "evalue": "",
     "output_type": "error",
     "traceback": [
      "\u001b[1;31mRunning cells with 'sis_cv_api' requires the ipykernel package.\n",
      "\u001b[1;31mRun the following command to install 'ipykernel' into the Python environment. \n",
      "\u001b[1;31mCommand: 'conda install -n sis_cv_api ipykernel --update-deps --force-reinstall'"
     ]
    }
   ],
   "source": [
    "accuracy = history.history['accuracy']\n",
    "val_accuracy = history.history['val_accuracy']\n",
    "loss = history.history['loss']\n",
    "val_loss = history.history['val_loss']\n",
    "\n",
    "epochs_range = range(epochs)\n",
    "\n",
    "plt.plot(epochs_range, accuracy, 'g', label='Training Accuracy')\n",
    "plt.plot(epochs_range, val_accuracy, 'b', label='Validation Accuracy')\n",
    "plt.legend()\n",
    "plt.figure()\n",
    "plt.title('Training / Validation Accuracy')\n",
    "\n",
    "plt.plot(epochs_range, loss, 'r', label='Training Loss')\n",
    "plt.plot(epochs_range, val_loss, 'y', label='Validation Loss')\n",
    "plt.title('Training / Validation Loss')\n",
    "plt.legend()\n",
    "plt.figure()"
   ]
  }
 ],
 "metadata": {
  "kernelspec": {
   "display_name": "sis_cv_api",
   "language": "python",
   "name": "python3"
  },
  "language_info": {
   "codemirror_mode": {
    "name": "ipython",
    "version": 3
   },
   "file_extension": ".py",
   "mimetype": "text/x-python",
   "name": "python",
   "nbconvert_exporter": "python",
   "pygments_lexer": "ipython3",
   "version": "3.11.4"
  },
  "orig_nbformat": 4
 },
 "nbformat": 4,
 "nbformat_minor": 2
}
